Heartbeat has not been acknowledged for 41.25 seconds, likely zombied connection. Reconnect!
POST /channels/1120192393329770547/messages Has exceeded its ratelimit (5)! Reset in 5.263 seconds
Ignoring exception in MessageCreate():
Traceback (most recent call last):
  File "/home/ubuntu/.local/lib/python3.10/site-packages/interactions/client/client.py", line 597, in _async_wrap
    await _coro(_event, *_args, **_kwargs)
  File "/home/ubuntu/.local/lib/python3.10/site-packages/interactions/models/internal/callback.py", line 31, in __call__
    return await self.callback(self._binding, *args, **kwargs)
  File "/home/ubuntu/FILO_LISTEN_BOT/App/apis/DiscordReply/BotEvent.py", line 147, in on_MessageCreate
    await message.reply(content = agency)
  File "/home/ubuntu/.local/lib/python3.10/site-packages/interactions/models/discord/message.py", line 701, in reply
    return await self.channel.send(content=content, reply_to=self, embeds=embeds or embed, **kwargs)
  File "/home/ubuntu/.local/lib/python3.10/site-packages/interactions/client/mixins/send.py", line 110, in send
    message_data = await self._send_http_request(message_payload, files=files or file)
  File "/home/ubuntu/.local/lib/python3.10/site-packages/interactions/models/discord/channel.py", line 247, in _send_http_request
    return await self._client.http.create_message(message_payload, self.id, files=files)
  File "/home/ubuntu/.local/lib/python3.10/site-packages/interactions/api/http/http_requests/messages.py", line 35, in create_message
    result = await self.request(
  File "/home/ubuntu/.local/lib/python3.10/site-packages/interactions/api/http/http_client.py", line 437, in request
    await lock.lock_for_duration(
  File "/home/ubuntu/.local/lib/python3.10/site-packages/interactions/api/http/http_client.py", line 179, in lock_for_duration
    raise RuntimeError("Attempted to lock a bucket that is already locked.")
RuntimeError: Attempted to lock a bucket that is already locked.

POST /channels/1120192393329770547/messages Has exceeded its ratelimit (5)! Reset in 5.95 seconds
POST /channels/1120192393329770547/messages Has exceeded its ratelimit (5)! Reset in 5.943 seconds
Ignoring exception in MessageCreate():
Traceback (most recent call last):
  File "/home/ubuntu/.local/lib/python3.10/site-packages/interactions/client/client.py", line 597, in _async_wrap
    await _coro(_event, *_args, **_kwargs)
  File "/home/ubuntu/.local/lib/python3.10/site-packages/interactions/models/internal/callback.py", line 31, in __call__
    return await self.callback(self._binding, *args, **kwargs)
  File "/home/ubuntu/FILO_LISTEN_BOT/App/apis/DiscordReply/BotEvent.py", line 147, in on_MessageCreate
    await message.reply(content = agency)
  File "/home/ubuntu/.local/lib/python3.10/site-packages/interactions/models/discord/message.py", line 701, in reply
    return await self.channel.send(content=content, reply_to=self, embeds=embeds or embed, **kwargs)
  File "/home/ubuntu/.local/lib/python3.10/site-packages/interactions/client/mixins/send.py", line 110, in send
    message_data = await self._send_http_request(message_payload, files=files or file)
  File "/home/ubuntu/.local/lib/python3.10/site-packages/interactions/models/discord/channel.py", line 247, in _send_http_request
    return await self._client.http.create_message(message_payload, self.id, files=files)
  File "/home/ubuntu/.local/lib/python3.10/site-packages/interactions/api/http/http_requests/messages.py", line 35, in create_message
    result = await self.request(
  File "/home/ubuntu/.local/lib/python3.10/site-packages/interactions/api/http/http_client.py", line 429, in request
    await lock.lock_for_duration(lock.delta, block=True)
  File "/home/ubuntu/.local/lib/python3.10/site-packages/interactions/api/http/http_client.py", line 179, in lock_for_duration
    raise RuntimeError("Attempted to lock a bucket that is already locked.")
RuntimeError: Attempted to lock a bucket that is already locked.

Ignoring exception in MessageCreate():
Traceback (most recent call last):
  File "/home/ubuntu/.local/lib/python3.10/site-packages/interactions/client/client.py", line 597, in _async_wrap
    await _coro(_event, *_args, **_kwargs)
  File "/home/ubuntu/.local/lib/python3.10/site-packages/interactions/models/internal/callback.py", line 31, in __call__
    return await self.callback(self._binding, *args, **kwargs)
  File "/home/ubuntu/FILO_LISTEN_BOT/App/apis/DiscordReply/BotEvent.py", line 147, in on_MessageCreate
    await message.reply(content = agency)
  File "/home/ubuntu/.local/lib/python3.10/site-packages/interactions/models/discord/message.py", line 701, in reply
    return await self.channel.send(content=content, reply_to=self, embeds=embeds or embed, **kwargs)
  File "/home/ubuntu/.local/lib/python3.10/site-packages/interactions/client/mixins/send.py", line 110, in send
    message_data = await self._send_http_request(message_payload, files=files or file)
  File "/home/ubuntu/.local/lib/python3.10/site-packages/interactions/models/discord/channel.py", line 247, in _send_http_request
    return await self._client.http.create_message(message_payload, self.id, files=files)
  File "/home/ubuntu/.local/lib/python3.10/site-packages/interactions/api/http/http_requests/messages.py", line 35, in create_message
    result = await self.request(
  File "/home/ubuntu/.local/lib/python3.10/site-packages/interactions/api/http/http_client.py", line 437, in request
    await lock.lock_for_duration(
  File "/home/ubuntu/.local/lib/python3.10/site-packages/interactions/api/http/http_client.py", line 179, in lock_for_duration
    raise RuntimeError("Attempted to lock a bucket that is already locked.")
RuntimeError: Attempted to lock a bucket that is already locked.

POST /channels/1120192393329770547/messages Has exceeded its ratelimit (5)! Reset in 5.949 seconds
POST /channels/1120192393329770547/messages Has exceeded its ratelimit (5)! Reset in 5.801 seconds
Ignoring exception in MessageCreate():
Traceback (most recent call last):
  File "/home/ubuntu/.local/lib/python3.10/site-packages/interactions/client/client.py", line 597, in _async_wrap
    await _coro(_event, *_args, **_kwargs)
  File "/home/ubuntu/.local/lib/python3.10/site-packages/interactions/models/internal/callback.py", line 31, in __call__
    return await self.callback(self._binding, *args, **kwargs)
  File "/home/ubuntu/FILO_LISTEN_BOT/App/apis/DiscordReply/BotEvent.py", line 147, in on_MessageCreate
    await message.reply(content = agency)
  File "/home/ubuntu/.local/lib/python3.10/site-packages/interactions/models/discord/message.py", line 701, in reply
    return await self.channel.send(content=content, reply_to=self, embeds=embeds or embed, **kwargs)
  File "/home/ubuntu/.local/lib/python3.10/site-packages/interactions/client/mixins/send.py", line 110, in send
    message_data = await self._send_http_request(message_payload, files=files or file)
  File "/home/ubuntu/.local/lib/python3.10/site-packages/interactions/models/discord/channel.py", line 247, in _send_http_request
    return await self._client.http.create_message(message_payload, self.id, files=files)
  File "/home/ubuntu/.local/lib/python3.10/site-packages/interactions/api/http/http_requests/messages.py", line 35, in create_message
    result = await self.request(
  File "/home/ubuntu/.local/lib/python3.10/site-packages/interactions/api/http/http_client.py", line 429, in request
    await lock.lock_for_duration(lock.delta, block=True)
  File "/home/ubuntu/.local/lib/python3.10/site-packages/interactions/api/http/http_client.py", line 179, in lock_for_duration
    raise RuntimeError("Attempted to lock a bucket that is already locked.")
RuntimeError: Attempted to lock a bucket that is already locked.

Ignoring exception in MessageCreate():
Traceback (most recent call last):
  File "/home/ubuntu/.local/lib/python3.10/site-packages/interactions/client/client.py", line 597, in _async_wrap
    await _coro(_event, *_args, **_kwargs)
  File "/home/ubuntu/.local/lib/python3.10/site-packages/interactions/models/internal/callback.py", line 31, in __call__
    return await self.callback(self._binding, *args, **kwargs)
  File "/home/ubuntu/FILO_LISTEN_BOT/App/apis/DiscordReply/BotEvent.py", line 147, in on_MessageCreate
    await message.reply(content = agency)
  File "/home/ubuntu/.local/lib/python3.10/site-packages/interactions/models/discord/message.py", line 701, in reply
    return await self.channel.send(content=content, reply_to=self, embeds=embeds or embed, **kwargs)
  File "/home/ubuntu/.local/lib/python3.10/site-packages/interactions/client/mixins/send.py", line 110, in send
    message_data = await self._send_http_request(message_payload, files=files or file)
  File "/home/ubuntu/.local/lib/python3.10/site-packages/interactions/models/discord/channel.py", line 247, in _send_http_request
    return await self._client.http.create_message(message_payload, self.id, files=files)
  File "/home/ubuntu/.local/lib/python3.10/site-packages/interactions/api/http/http_requests/messages.py", line 35, in create_message
    result = await self.request(
  File "/home/ubuntu/.local/lib/python3.10/site-packages/interactions/api/http/http_client.py", line 437, in request
    await lock.lock_for_duration(
  File "/home/ubuntu/.local/lib/python3.10/site-packages/interactions/api/http/http_client.py", line 179, in lock_for_duration
    raise RuntimeError("Attempted to lock a bucket that is already locked.")
RuntimeError: Attempted to lock a bucket that is already locked.

POST /channels/1120192393329770547/messages Has exceeded its ratelimit (5)! Reset in 5.968 seconds
POST /channels/1120192393329770547/messages Has exceeded its ratelimit (5)! Reset in 5.832 seconds
Ignoring exception in MessageCreate():
Traceback (most recent call last):
  File "/home/ubuntu/.local/lib/python3.10/site-packages/interactions/client/client.py", line 597, in _async_wrap
    await _coro(_event, *_args, **_kwargs)
  File "/home/ubuntu/.local/lib/python3.10/site-packages/interactions/models/internal/callback.py", line 31, in __call__
    return await self.callback(self._binding, *args, **kwargs)
  File "/home/ubuntu/FILO_LISTEN_BOT/App/apis/DiscordReply/BotEvent.py", line 147, in on_MessageCreate
    await message.reply(content = agency)
  File "/home/ubuntu/.local/lib/python3.10/site-packages/interactions/models/discord/message.py", line 701, in reply
    return await self.channel.send(content=content, reply_to=self, embeds=embeds or embed, **kwargs)
  File "/home/ubuntu/.local/lib/python3.10/site-packages/interactions/client/mixins/send.py", line 110, in send
    message_data = await self._send_http_request(message_payload, files=files or file)
  File "/home/ubuntu/.local/lib/python3.10/site-packages/interactions/models/discord/channel.py", line 247, in _send_http_request
    return await self._client.http.create_message(message_payload, self.id, files=files)
  File "/home/ubuntu/.local/lib/python3.10/site-packages/interactions/api/http/http_requests/messages.py", line 35, in create_message
    result = await self.request(
  File "/home/ubuntu/.local/lib/python3.10/site-packages/interactions/api/http/http_client.py", line 429, in request
    await lock.lock_for_duration(lock.delta, block=True)
  File "/home/ubuntu/.local/lib/python3.10/site-packages/interactions/api/http/http_client.py", line 179, in lock_for_duration
    raise RuntimeError("Attempted to lock a bucket that is already locked.")
RuntimeError: Attempted to lock a bucket that is already locked.

Ignoring exception in MessageCreate():
Traceback (most recent call last):
  File "/home/ubuntu/.local/lib/python3.10/site-packages/interactions/client/client.py", line 597, in _async_wrap
    await _coro(_event, *_args, **_kwargs)
  File "/home/ubuntu/.local/lib/python3.10/site-packages/interactions/models/internal/callback.py", line 31, in __call__
    return await self.callback(self._binding, *args, **kwargs)
  File "/home/ubuntu/FILO_LISTEN_BOT/App/apis/DiscordReply/BotEvent.py", line 147, in on_MessageCreate
    await message.reply(content = agency)
  File "/home/ubuntu/.local/lib/python3.10/site-packages/interactions/models/discord/message.py", line 701, in reply
    return await self.channel.send(content=content, reply_to=self, embeds=embeds or embed, **kwargs)
  File "/home/ubuntu/.local/lib/python3.10/site-packages/interactions/client/mixins/send.py", line 110, in send
    message_data = await self._send_http_request(message_payload, files=files or file)
  File "/home/ubuntu/.local/lib/python3.10/site-packages/interactions/models/discord/channel.py", line 247, in _send_http_request
    return await self._client.http.create_message(message_payload, self.id, files=files)
  File "/home/ubuntu/.local/lib/python3.10/site-packages/interactions/api/http/http_requests/messages.py", line 35, in create_message
    result = await self.request(
  File "/home/ubuntu/.local/lib/python3.10/site-packages/interactions/api/http/http_client.py", line 437, in request
    await lock.lock_for_duration(
  File "/home/ubuntu/.local/lib/python3.10/site-packages/interactions/api/http/http_client.py", line 179, in lock_for_duration
    raise RuntimeError("Attempted to lock a bucket that is already locked.")
RuntimeError: Attempted to lock a bucket that is already locked.

POST /channels/1120192393329770547/messages Has exceeded its ratelimit (5)! Reset in 5.78 seconds
Ignoring exception in MessageCreate():
Traceback (most recent call last):
  File "/home/ubuntu/.local/lib/python3.10/site-packages/interactions/client/client.py", line 597, in _async_wrap
    await _coro(_event, *_args, **_kwargs)
  File "/home/ubuntu/.local/lib/python3.10/site-packages/interactions/models/internal/callback.py", line 31, in __call__
    return await self.callback(self._binding, *args, **kwargs)
  File "/home/ubuntu/FILO_LISTEN_BOT/App/apis/DiscordReply/BotEvent.py", line 147, in on_MessageCreate
    await message.reply(content = agency)
  File "/home/ubuntu/.local/lib/python3.10/site-packages/interactions/models/discord/message.py", line 701, in reply
    return await self.channel.send(content=content, reply_to=self, embeds=embeds or embed, **kwargs)
  File "/home/ubuntu/.local/lib/python3.10/site-packages/interactions/client/mixins/send.py", line 110, in send
    message_data = await self._send_http_request(message_payload, files=files or file)
  File "/home/ubuntu/.local/lib/python3.10/site-packages/interactions/models/discord/channel.py", line 247, in _send_http_request
    return await self._client.http.create_message(message_payload, self.id, files=files)
  File "/home/ubuntu/.local/lib/python3.10/site-packages/interactions/api/http/http_requests/messages.py", line 35, in create_message
    result = await self.request(
  File "/home/ubuntu/.local/lib/python3.10/site-packages/interactions/api/http/http_client.py", line 429, in request
    await lock.lock_for_duration(lock.delta, block=True)
  File "/home/ubuntu/.local/lib/python3.10/site-packages/interactions/api/http/http_client.py", line 179, in lock_for_duration
    raise RuntimeError("Attempted to lock a bucket that is already locked.")
RuntimeError: Attempted to lock a bucket that is already locked.

POST /channels/1120192393329770547/messages Has exceeded its ratelimit (5)! Reset in 5.956 seconds
Ignoring exception in MessageCreate():
Traceback (most recent call last):
  File "/home/ubuntu/.local/lib/python3.10/site-packages/interactions/client/client.py", line 597, in _async_wrap
    await _coro(_event, *_args, **_kwargs)
  File "/home/ubuntu/.local/lib/python3.10/site-packages/interactions/models/internal/callback.py", line 31, in __call__
    return await self.callback(self._binding, *args, **kwargs)
  File "/home/ubuntu/FILO_LISTEN_BOT/App/apis/DiscordReply/BotEvent.py", line 147, in on_MessageCreate
    await message.reply(content = agency)
  File "/home/ubuntu/.local/lib/python3.10/site-packages/interactions/models/discord/message.py", line 701, in reply
    return await self.channel.send(content=content, reply_to=self, embeds=embeds or embed, **kwargs)
  File "/home/ubuntu/.local/lib/python3.10/site-packages/interactions/client/mixins/send.py", line 110, in send
    message_data = await self._send_http_request(message_payload, files=files or file)
  File "/home/ubuntu/.local/lib/python3.10/site-packages/interactions/models/discord/channel.py", line 247, in _send_http_request
    return await self._client.http.create_message(message_payload, self.id, files=files)
  File "/home/ubuntu/.local/lib/python3.10/site-packages/interactions/api/http/http_requests/messages.py", line 35, in create_message
    result = await self.request(
  File "/home/ubuntu/.local/lib/python3.10/site-packages/interactions/api/http/http_client.py", line 437, in request
    await lock.lock_for_duration(
  File "/home/ubuntu/.local/lib/python3.10/site-packages/interactions/api/http/http_client.py", line 179, in lock_for_duration
    raise RuntimeError("Attempted to lock a bucket that is already locked.")
RuntimeError: Attempted to lock a bucket that is already locked.

POST /channels/1120192393329770547/messages Has exceeded its ratelimit (5)! Reset in 5.968 seconds
Ignoring exception in MessageCreate():
Traceback (most recent call last):
  File "/home/ubuntu/.local/lib/python3.10/site-packages/interactions/client/client.py", line 597, in _async_wrap
    await _coro(_event, *_args, **_kwargs)
  File "/home/ubuntu/.local/lib/python3.10/site-packages/interactions/models/internal/callback.py", line 31, in __call__
    return await self.callback(self._binding, *args, **kwargs)
  File "/home/ubuntu/FILO_LISTEN_BOT/App/apis/DiscordReply/BotEvent.py", line 147, in on_MessageCreate
    await message.reply(content = agency)
  File "/home/ubuntu/.local/lib/python3.10/site-packages/interactions/models/discord/message.py", line 701, in reply
    return await self.channel.send(content=content, reply_to=self, embeds=embeds or embed, **kwargs)
  File "/home/ubuntu/.local/lib/python3.10/site-packages/interactions/client/mixins/send.py", line 110, in send
    message_data = await self._send_http_request(message_payload, files=files or file)
  File "/home/ubuntu/.local/lib/python3.10/site-packages/interactions/models/discord/channel.py", line 247, in _send_http_request
    return await self._client.http.create_message(message_payload, self.id, files=files)
  File "/home/ubuntu/.local/lib/python3.10/site-packages/interactions/api/http/http_requests/messages.py", line 35, in create_message
    result = await self.request(
  File "/home/ubuntu/.local/lib/python3.10/site-packages/interactions/api/http/http_client.py", line 437, in request
    await lock.lock_for_duration(
  File "/home/ubuntu/.local/lib/python3.10/site-packages/interactions/api/http/http_client.py", line 179, in lock_for_duration
    raise RuntimeError("Attempted to lock a bucket that is already locked.")
RuntimeError: Attempted to lock a bucket that is already locked.

POST /channels/1120192393329770547/messages Has exceeded its ratelimit (5)! Reset in 5.968 seconds
POST /channels/1120192393329770547/messages Has exceeded its ratelimit (5)! Reset in 5.945 seconds
Ignoring exception in MessageCreate():
Traceback (most recent call last):
  File "/home/ubuntu/.local/lib/python3.10/site-packages/interactions/client/client.py", line 597, in _async_wrap
    await _coro(_event, *_args, **_kwargs)
  File "/home/ubuntu/.local/lib/python3.10/site-packages/interactions/models/internal/callback.py", line 31, in __call__
    return await self.callback(self._binding, *args, **kwargs)
  File "/home/ubuntu/FILO_LISTEN_BOT/App/apis/DiscordReply/BotEvent.py", line 147, in on_MessageCreate
    await message.reply(content = agency)
  File "/home/ubuntu/.local/lib/python3.10/site-packages/interactions/models/discord/message.py", line 701, in reply
    return await self.channel.send(content=content, reply_to=self, embeds=embeds or embed, **kwargs)
  File "/home/ubuntu/.local/lib/python3.10/site-packages/interactions/client/mixins/send.py", line 110, in send
    message_data = await self._send_http_request(message_payload, files=files or file)
  File "/home/ubuntu/.local/lib/python3.10/site-packages/interactions/models/discord/channel.py", line 247, in _send_http_request
    return await self._client.http.create_message(message_payload, self.id, files=files)
  File "/home/ubuntu/.local/lib/python3.10/site-packages/interactions/api/http/http_requests/messages.py", line 35, in create_message
    result = await self.request(
  File "/home/ubuntu/.local/lib/python3.10/site-packages/interactions/api/http/http_client.py", line 429, in request
    await lock.lock_for_duration(lock.delta, block=True)
  File "/home/ubuntu/.local/lib/python3.10/site-packages/interactions/api/http/http_client.py", line 179, in lock_for_duration
    raise RuntimeError("Attempted to lock a bucket that is already locked.")
RuntimeError: Attempted to lock a bucket that is already locked.

Ignoring exception in MessageCreate():
Traceback (most recent call last):
  File "/home/ubuntu/.local/lib/python3.10/site-packages/interactions/client/client.py", line 597, in _async_wrap
    await _coro(_event, *_args, **_kwargs)
  File "/home/ubuntu/.local/lib/python3.10/site-packages/interactions/models/internal/callback.py", line 31, in __call__
    return await self.callback(self._binding, *args, **kwargs)
  File "/home/ubuntu/FILO_LISTEN_BOT/App/apis/DiscordReply/BotEvent.py", line 147, in on_MessageCreate
    await message.reply(content = agency)
  File "/home/ubuntu/.local/lib/python3.10/site-packages/interactions/models/discord/message.py", line 701, in reply
    return await self.channel.send(content=content, reply_to=self, embeds=embeds or embed, **kwargs)
  File "/home/ubuntu/.local/lib/python3.10/site-packages/interactions/client/mixins/send.py", line 110, in send
    message_data = await self._send_http_request(message_payload, files=files or file)
  File "/home/ubuntu/.local/lib/python3.10/site-packages/interactions/models/discord/channel.py", line 247, in _send_http_request
    return await self._client.http.create_message(message_payload, self.id, files=files)
  File "/home/ubuntu/.local/lib/python3.10/site-packages/interactions/api/http/http_requests/messages.py", line 35, in create_message
    result = await self.request(
  File "/home/ubuntu/.local/lib/python3.10/site-packages/interactions/api/http/http_client.py", line 437, in request
    await lock.lock_for_duration(
  File "/home/ubuntu/.local/lib/python3.10/site-packages/interactions/api/http/http_client.py", line 179, in lock_for_duration
    raise RuntimeError("Attempted to lock a bucket that is already locked.")
RuntimeError: Attempted to lock a bucket that is already locked.

POST /channels/1120192393329770547/messages Has exceeded its ratelimit (5)! Reset in 5.973 seconds
POST /channels/1120192393329770547/messages Has exceeded its ratelimit (5)! Reset in 5.953 seconds
Ignoring exception in MessageCreate():
Traceback (most recent call last):
  File "/home/ubuntu/.local/lib/python3.10/site-packages/interactions/client/client.py", line 597, in _async_wrap
    await _coro(_event, *_args, **_kwargs)
  File "/home/ubuntu/.local/lib/python3.10/site-packages/interactions/models/internal/callback.py", line 31, in __call__
    return await self.callback(self._binding, *args, **kwargs)
  File "/home/ubuntu/FILO_LISTEN_BOT/App/apis/DiscordReply/BotEvent.py", line 147, in on_MessageCreate
    await message.reply(content = agency)
  File "/home/ubuntu/.local/lib/python3.10/site-packages/interactions/models/discord/message.py", line 701, in reply
    return await self.channel.send(content=content, reply_to=self, embeds=embeds or embed, **kwargs)
  File "/home/ubuntu/.local/lib/python3.10/site-packages/interactions/client/mixins/send.py", line 110, in send
    message_data = await self._send_http_request(message_payload, files=files or file)
  File "/home/ubuntu/.local/lib/python3.10/site-packages/interactions/models/discord/channel.py", line 247, in _send_http_request
    return await self._client.http.create_message(message_payload, self.id, files=files)
  File "/home/ubuntu/.local/lib/python3.10/site-packages/interactions/api/http/http_requests/messages.py", line 35, in create_message
    result = await self.request(
  File "/home/ubuntu/.local/lib/python3.10/site-packages/interactions/api/http/http_client.py", line 429, in request
    await lock.lock_for_duration(lock.delta, block=True)
  File "/home/ubuntu/.local/lib/python3.10/site-packages/interactions/api/http/http_client.py", line 179, in lock_for_duration
    raise RuntimeError("Attempted to lock a bucket that is already locked.")
RuntimeError: Attempted to lock a bucket that is already locked.

Ignoring exception in MessageCreate():
Traceback (most recent call last):
  File "/home/ubuntu/.local/lib/python3.10/site-packages/interactions/client/client.py", line 597, in _async_wrap
    await _coro(_event, *_args, **_kwargs)
  File "/home/ubuntu/.local/lib/python3.10/site-packages/interactions/models/internal/callback.py", line 31, in __call__
    return await self.callback(self._binding, *args, **kwargs)
  File "/home/ubuntu/FILO_LISTEN_BOT/App/apis/DiscordReply/BotEvent.py", line 147, in on_MessageCreate
    await message.reply(content = agency)
  File "/home/ubuntu/.local/lib/python3.10/site-packages/interactions/models/discord/message.py", line 701, in reply
    return await self.channel.send(content=content, reply_to=self, embeds=embeds or embed, **kwargs)
  File "/home/ubuntu/.local/lib/python3.10/site-packages/interactions/client/mixins/send.py", line 110, in send
    message_data = await self._send_http_request(message_payload, files=files or file)
  File "/home/ubuntu/.local/lib/python3.10/site-packages/interactions/models/discord/channel.py", line 247, in _send_http_request
    return await self._client.http.create_message(message_payload, self.id, files=files)
  File "/home/ubuntu/.local/lib/python3.10/site-packages/interactions/api/http/http_requests/messages.py", line 35, in create_message
    result = await self.request(
  File "/home/ubuntu/.local/lib/python3.10/site-packages/interactions/api/http/http_client.py", line 437, in request
    await lock.lock_for_duration(
  File "/home/ubuntu/.local/lib/python3.10/site-packages/interactions/api/http/http_client.py", line 179, in lock_for_duration
    raise RuntimeError("Attempted to lock a bucket that is already locked.")
RuntimeError: Attempted to lock a bucket that is already locked.

POST /channels/1120192393329770547/messages Has exceeded its ratelimit (5)! Reset in 5.968 seconds
POST /channels/1120192393329770547/messages Has exceeded its ratelimit (5)! Reset in 5.961 seconds
Ignoring exception in MessageCreate():
Traceback (most recent call last):
  File "/home/ubuntu/.local/lib/python3.10/site-packages/interactions/client/client.py", line 597, in _async_wrap
    await _coro(_event, *_args, **_kwargs)
  File "/home/ubuntu/.local/lib/python3.10/site-packages/interactions/models/internal/callback.py", line 31, in __call__
    return await self.callback(self._binding, *args, **kwargs)
  File "/home/ubuntu/FILO_LISTEN_BOT/App/apis/DiscordReply/BotEvent.py", line 147, in on_MessageCreate
    await message.reply(content = agency)
  File "/home/ubuntu/.local/lib/python3.10/site-packages/interactions/models/discord/message.py", line 701, in reply
    return await self.channel.send(content=content, reply_to=self, embeds=embeds or embed, **kwargs)
  File "/home/ubuntu/.local/lib/python3.10/site-packages/interactions/client/mixins/send.py", line 110, in send
    message_data = await self._send_http_request(message_payload, files=files or file)
  File "/home/ubuntu/.local/lib/python3.10/site-packages/interactions/models/discord/channel.py", line 247, in _send_http_request
    return await self._client.http.create_message(message_payload, self.id, files=files)
  File "/home/ubuntu/.local/lib/python3.10/site-packages/interactions/api/http/http_requests/messages.py", line 35, in create_message
    result = await self.request(
  File "/home/ubuntu/.local/lib/python3.10/site-packages/interactions/api/http/http_client.py", line 429, in request
    await lock.lock_for_duration(lock.delta, block=True)
  File "/home/ubuntu/.local/lib/python3.10/site-packages/interactions/api/http/http_client.py", line 179, in lock_for_duration
    raise RuntimeError("Attempted to lock a bucket that is already locked.")
RuntimeError: Attempted to lock a bucket that is already locked.

Ignoring exception in MessageCreate():
Traceback (most recent call last):
  File "/home/ubuntu/.local/lib/python3.10/site-packages/interactions/client/client.py", line 597, in _async_wrap
    await _coro(_event, *_args, **_kwargs)
  File "/home/ubuntu/.local/lib/python3.10/site-packages/interactions/models/internal/callback.py", line 31, in __call__
    return await self.callback(self._binding, *args, **kwargs)
  File "/home/ubuntu/FILO_LISTEN_BOT/App/apis/DiscordReply/BotEvent.py", line 147, in on_MessageCreate
    await message.reply(content = agency)
  File "/home/ubuntu/.local/lib/python3.10/site-packages/interactions/models/discord/message.py", line 701, in reply
    return await self.channel.send(content=content, reply_to=self, embeds=embeds or embed, **kwargs)
  File "/home/ubuntu/.local/lib/python3.10/site-packages/interactions/client/mixins/send.py", line 110, in send
    message_data = await self._send_http_request(message_payload, files=files or file)
  File "/home/ubuntu/.local/lib/python3.10/site-packages/interactions/models/discord/channel.py", line 247, in _send_http_request
    return await self._client.http.create_message(message_payload, self.id, files=files)
  File "/home/ubuntu/.local/lib/python3.10/site-packages/interactions/api/http/http_requests/messages.py", line 35, in create_message
    result = await self.request(
  File "/home/ubuntu/.local/lib/python3.10/site-packages/interactions/api/http/http_client.py", line 437, in request
    await lock.lock_for_duration(
  File "/home/ubuntu/.local/lib/python3.10/site-packages/interactions/api/http/http_client.py", line 179, in lock_for_duration
    raise RuntimeError("Attempted to lock a bucket that is already locked.")
RuntimeError: Attempted to lock a bucket that is already locked.

POST /channels/1120192393329770547/messages Has exceeded its ratelimit (5)! Reset in 5.953 seconds
POST /channels/1120192393329770547/messages Has exceeded its ratelimit (5)! Reset in 5.888 seconds
Ignoring exception in MessageCreate():
Traceback (most recent call last):
  File "/home/ubuntu/.local/lib/python3.10/site-packages/interactions/client/client.py", line 597, in _async_wrap
    await _coro(_event, *_args, **_kwargs)
  File "/home/ubuntu/.local/lib/python3.10/site-packages/interactions/models/internal/callback.py", line 31, in __call__
    return await self.callback(self._binding, *args, **kwargs)
  File "/home/ubuntu/FILO_LISTEN_BOT/App/apis/DiscordReply/BotEvent.py", line 147, in on_MessageCreate
    await message.reply(content = agency)
  File "/home/ubuntu/.local/lib/python3.10/site-packages/interactions/models/discord/message.py", line 701, in reply
    return await self.channel.send(content=content, reply_to=self, embeds=embeds or embed, **kwargs)
  File "/home/ubuntu/.local/lib/python3.10/site-packages/interactions/client/mixins/send.py", line 110, in send
    message_data = await self._send_http_request(message_payload, files=files or file)
  File "/home/ubuntu/.local/lib/python3.10/site-packages/interactions/models/discord/channel.py", line 247, in _send_http_request
    return await self._client.http.create_message(message_payload, self.id, files=files)
  File "/home/ubuntu/.local/lib/python3.10/site-packages/interactions/api/http/http_requests/messages.py", line 35, in create_message
    result = await self.request(
  File "/home/ubuntu/.local/lib/python3.10/site-packages/interactions/api/http/http_client.py", line 429, in request
    await lock.lock_for_duration(lock.delta, block=True)
  File "/home/ubuntu/.local/lib/python3.10/site-packages/interactions/api/http/http_client.py", line 179, in lock_for_duration
    raise RuntimeError("Attempted to lock a bucket that is already locked.")
RuntimeError: Attempted to lock a bucket that is already locked.

Ignoring exception in MessageCreate():
Traceback (most recent call last):
  File "/home/ubuntu/.local/lib/python3.10/site-packages/interactions/client/client.py", line 597, in _async_wrap
    await _coro(_event, *_args, **_kwargs)
  File "/home/ubuntu/.local/lib/python3.10/site-packages/interactions/models/internal/callback.py", line 31, in __call__
    return await self.callback(self._binding, *args, **kwargs)
  File "/home/ubuntu/FILO_LISTEN_BOT/App/apis/DiscordReply/BotEvent.py", line 147, in on_MessageCreate
    await message.reply(content = agency)
  File "/home/ubuntu/.local/lib/python3.10/site-packages/interactions/models/discord/message.py", line 701, in reply
    return await self.channel.send(content=content, reply_to=self, embeds=embeds or embed, **kwargs)
  File "/home/ubuntu/.local/lib/python3.10/site-packages/interactions/client/mixins/send.py", line 110, in send
    message_data = await self._send_http_request(message_payload, files=files or file)
  File "/home/ubuntu/.local/lib/python3.10/site-packages/interactions/models/discord/channel.py", line 247, in _send_http_request
    return await self._client.http.create_message(message_payload, self.id, files=files)
  File "/home/ubuntu/.local/lib/python3.10/site-packages/interactions/api/http/http_requests/messages.py", line 35, in create_message
    result = await self.request(
  File "/home/ubuntu/.local/lib/python3.10/site-packages/interactions/api/http/http_client.py", line 437, in request
    await lock.lock_for_duration(
  File "/home/ubuntu/.local/lib/python3.10/site-packages/interactions/api/http/http_client.py", line 179, in lock_for_duration
    raise RuntimeError("Attempted to lock a bucket that is already locked.")
RuntimeError: Attempted to lock a bucket that is already locked.

POST /channels/1120192393329770547/messages Has exceeded its ratelimit (5)! Reset in 5.968 seconds
POST /channels/1120192393329770547/messages Has exceeded its ratelimit (5)! Reset in 5.961 seconds
Ignoring exception in MessageCreate():
Traceback (most recent call last):
  File "/home/ubuntu/.local/lib/python3.10/site-packages/interactions/client/client.py", line 597, in _async_wrap
    await _coro(_event, *_args, **_kwargs)
  File "/home/ubuntu/.local/lib/python3.10/site-packages/interactions/models/internal/callback.py", line 31, in __call__
    return await self.callback(self._binding, *args, **kwargs)
  File "/home/ubuntu/FILO_LISTEN_BOT/App/apis/DiscordReply/BotEvent.py", line 147, in on_MessageCreate
    await message.reply(content = agency)
  File "/home/ubuntu/.local/lib/python3.10/site-packages/interactions/models/discord/message.py", line 701, in reply
    return await self.channel.send(content=content, reply_to=self, embeds=embeds or embed, **kwargs)
  File "/home/ubuntu/.local/lib/python3.10/site-packages/interactions/client/mixins/send.py", line 110, in send
    message_data = await self._send_http_request(message_payload, files=files or file)
  File "/home/ubuntu/.local/lib/python3.10/site-packages/interactions/models/discord/channel.py", line 247, in _send_http_request
    return await self._client.http.create_message(message_payload, self.id, files=files)
  File "/home/ubuntu/.local/lib/python3.10/site-packages/interactions/api/http/http_requests/messages.py", line 35, in create_message
    result = await self.request(
  File "/home/ubuntu/.local/lib/python3.10/site-packages/interactions/api/http/http_client.py", line 429, in request
    await lock.lock_for_duration(lock.delta, block=True)
  File "/home/ubuntu/.local/lib/python3.10/site-packages/interactions/api/http/http_client.py", line 179, in lock_for_duration
    raise RuntimeError("Attempted to lock a bucket that is already locked.")
RuntimeError: Attempted to lock a bucket that is already locked.

Ignoring exception in MessageCreate():
Traceback (most recent call last):
  File "/home/ubuntu/.local/lib/python3.10/site-packages/interactions/client/client.py", line 597, in _async_wrap
    await _coro(_event, *_args, **_kwargs)
  File "/home/ubuntu/.local/lib/python3.10/site-packages/interactions/models/internal/callback.py", line 31, in __call__
    return await self.callback(self._binding, *args, **kwargs)
  File "/home/ubuntu/FILO_LISTEN_BOT/App/apis/DiscordReply/BotEvent.py", line 147, in on_MessageCreate
    await message.reply(content = agency)
  File "/home/ubuntu/.local/lib/python3.10/site-packages/interactions/models/discord/message.py", line 701, in reply
    return await self.channel.send(content=content, reply_to=self, embeds=embeds or embed, **kwargs)
  File "/home/ubuntu/.local/lib/python3.10/site-packages/interactions/client/mixins/send.py", line 110, in send
    message_data = await self._send_http_request(message_payload, files=files or file)
  File "/home/ubuntu/.local/lib/python3.10/site-packages/interactions/models/discord/channel.py", line 247, in _send_http_request
    return await self._client.http.create_message(message_payload, self.id, files=files)
  File "/home/ubuntu/.local/lib/python3.10/site-packages/interactions/api/http/http_requests/messages.py", line 35, in create_message
    result = await self.request(
  File "/home/ubuntu/.local/lib/python3.10/site-packages/interactions/api/http/http_client.py", line 437, in request
    await lock.lock_for_duration(
  File "/home/ubuntu/.local/lib/python3.10/site-packages/interactions/api/http/http_client.py", line 179, in lock_for_duration
    raise RuntimeError("Attempted to lock a bucket that is already locked.")
RuntimeError: Attempted to lock a bucket that is already locked.

POST /channels/1120192393329770547/messages Has exceeded its ratelimit (5)! Reset in 5.977 seconds
POST /channels/1120192393329770547/messages Has exceeded its ratelimit (5)! Reset in 5.972 seconds
Ignoring exception in MessageCreate():
Traceback (most recent call last):
  File "/home/ubuntu/.local/lib/python3.10/site-packages/interactions/client/client.py", line 597, in _async_wrap
    await _coro(_event, *_args, **_kwargs)
  File "/home/ubuntu/.local/lib/python3.10/site-packages/interactions/models/internal/callback.py", line 31, in __call__
    return await self.callback(self._binding, *args, **kwargs)
  File "/home/ubuntu/FILO_LISTEN_BOT/App/apis/DiscordReply/BotEvent.py", line 147, in on_MessageCreate
    await message.reply(content = agency)
  File "/home/ubuntu/.local/lib/python3.10/site-packages/interactions/models/discord/message.py", line 701, in reply
    return await self.channel.send(content=content, reply_to=self, embeds=embeds or embed, **kwargs)
  File "/home/ubuntu/.local/lib/python3.10/site-packages/interactions/client/mixins/send.py", line 110, in send
    message_data = await self._send_http_request(message_payload, files=files or file)
  File "/home/ubuntu/.local/lib/python3.10/site-packages/interactions/models/discord/channel.py", line 247, in _send_http_request
    return await self._client.http.create_message(message_payload, self.id, files=files)
  File "/home/ubuntu/.local/lib/python3.10/site-packages/interactions/api/http/http_requests/messages.py", line 35, in create_message
    result = await self.request(
  File "/home/ubuntu/.local/lib/python3.10/site-packages/interactions/api/http/http_client.py", line 429, in request
    await lock.lock_for_duration(lock.delta, block=True)
  File "/home/ubuntu/.local/lib/python3.10/site-packages/interactions/api/http/http_client.py", line 179, in lock_for_duration
    raise RuntimeError("Attempted to lock a bucket that is already locked.")
RuntimeError: Attempted to lock a bucket that is already locked.

Ignoring exception in MessageCreate():
Traceback (most recent call last):
  File "/home/ubuntu/.local/lib/python3.10/site-packages/interactions/client/client.py", line 597, in _async_wrap
    await _coro(_event, *_args, **_kwargs)
  File "/home/ubuntu/.local/lib/python3.10/site-packages/interactions/models/internal/callback.py", line 31, in __call__
    return await self.callback(self._binding, *args, **kwargs)
  File "/home/ubuntu/FILO_LISTEN_BOT/App/apis/DiscordReply/BotEvent.py", line 147, in on_MessageCreate
    await message.reply(content = agency)
  File "/home/ubuntu/.local/lib/python3.10/site-packages/interactions/models/discord/message.py", line 701, in reply
    return await self.channel.send(content=content, reply_to=self, embeds=embeds or embed, **kwargs)
  File "/home/ubuntu/.local/lib/python3.10/site-packages/interactions/client/mixins/send.py", line 110, in send
    message_data = await self._send_http_request(message_payload, files=files or file)
  File "/home/ubuntu/.local/lib/python3.10/site-packages/interactions/models/discord/channel.py", line 247, in _send_http_request
    return await self._client.http.create_message(message_payload, self.id, files=files)
  File "/home/ubuntu/.local/lib/python3.10/site-packages/interactions/api/http/http_requests/messages.py", line 35, in create_message
    result = await self.request(
  File "/home/ubuntu/.local/lib/python3.10/site-packages/interactions/api/http/http_client.py", line 437, in request
    await lock.lock_for_duration(
  File "/home/ubuntu/.local/lib/python3.10/site-packages/interactions/api/http/http_client.py", line 179, in lock_for_duration
    raise RuntimeError("Attempted to lock a bucket that is already locked.")
RuntimeError: Attempted to lock a bucket that is already locked.

Task was destroyed but it is pending!
task: <Task pending name='interactions:: message_create' coro=<Client._queue_task.<locals>._async_wrap() running at /home/ubuntu/.local/lib/python3.10/site-packages/interactions/client/client.py:597> wait_for=<Future pending cb=[Task.task_wakeup()]>>
Task was destroyed but it is pending!
task: <Task pending name='interactions:: message_create' coro=<Client._queue_task.<locals>._async_wrap() running at /home/ubuntu/.local/lib/python3.10/site-packages/interactions/client/client.py:597> wait_for=<Future pending cb=[Task.task_wakeup()]>>
Task was destroyed but it is pending!
task: <Task pending name='interactions:: message_create' coro=<Client._queue_task.<locals>._async_wrap() running at /home/ubuntu/.local/lib/python3.10/site-packages/interactions/client/client.py:597> wait_for=<Future pending cb=[Task.task_wakeup()]>>
POST /channels/1120192393329770547/messages Has exceeded its ratelimit (5)! Reset in 5.978 seconds
POST /channels/1120192393329770547/messages Has exceeded its ratelimit (5)! Reset in 5.974 seconds
Ignoring exception in MessageCreate():
Traceback (most recent call last):
  File "/home/ubuntu/.local/lib/python3.10/site-packages/interactions/client/client.py", line 597, in _async_wrap
    await _coro(_event, *_args, **_kwargs)
  File "/home/ubuntu/.local/lib/python3.10/site-packages/interactions/models/internal/callback.py", line 31, in __call__
    return await self.callback(self._binding, *args, **kwargs)
  File "/home/ubuntu/FILO_LISTEN_BOT/App/apis/DiscordReply/BotEvent.py", line 147, in on_MessageCreate
    await message.reply(content = agency)
  File "/home/ubuntu/.local/lib/python3.10/site-packages/interactions/models/discord/message.py", line 701, in reply
    return await self.channel.send(content=content, reply_to=self, embeds=embeds or embed, **kwargs)
  File "/home/ubuntu/.local/lib/python3.10/site-packages/interactions/client/mixins/send.py", line 110, in send
    message_data = await self._send_http_request(message_payload, files=files or file)
  File "/home/ubuntu/.local/lib/python3.10/site-packages/interactions/models/discord/channel.py", line 247, in _send_http_request
    return await self._client.http.create_message(message_payload, self.id, files=files)
  File "/home/ubuntu/.local/lib/python3.10/site-packages/interactions/api/http/http_requests/messages.py", line 35, in create_message
    result = await self.request(
  File "/home/ubuntu/.local/lib/python3.10/site-packages/interactions/api/http/http_client.py", line 429, in request
    await lock.lock_for_duration(lock.delta, block=True)
  File "/home/ubuntu/.local/lib/python3.10/site-packages/interactions/api/http/http_client.py", line 179, in lock_for_duration
    raise RuntimeError("Attempted to lock a bucket that is already locked.")
RuntimeError: Attempted to lock a bucket that is already locked.

Ignoring exception in MessageCreate():
Traceback (most recent call last):
  File "/home/ubuntu/.local/lib/python3.10/site-packages/interactions/client/client.py", line 597, in _async_wrap
    await _coro(_event, *_args, **_kwargs)
  File "/home/ubuntu/.local/lib/python3.10/site-packages/interactions/models/internal/callback.py", line 31, in __call__
    return await self.callback(self._binding, *args, **kwargs)
  File "/home/ubuntu/FILO_LISTEN_BOT/App/apis/DiscordReply/BotEvent.py", line 147, in on_MessageCreate
    await message.reply(content = agency)
  File "/home/ubuntu/.local/lib/python3.10/site-packages/interactions/models/discord/message.py", line 701, in reply
    return await self.channel.send(content=content, reply_to=self, embeds=embeds or embed, **kwargs)
  File "/home/ubuntu/.local/lib/python3.10/site-packages/interactions/client/mixins/send.py", line 110, in send
    message_data = await self._send_http_request(message_payload, files=files or file)
  File "/home/ubuntu/.local/lib/python3.10/site-packages/interactions/models/discord/channel.py", line 247, in _send_http_request
    return await self._client.http.create_message(message_payload, self.id, files=files)
  File "/home/ubuntu/.local/lib/python3.10/site-packages/interactions/api/http/http_requests/messages.py", line 35, in create_message
    result = await self.request(
  File "/home/ubuntu/.local/lib/python3.10/site-packages/interactions/api/http/http_client.py", line 437, in request
    await lock.lock_for_duration(
  File "/home/ubuntu/.local/lib/python3.10/site-packages/interactions/api/http/http_client.py", line 179, in lock_for_duration
    raise RuntimeError("Attempted to lock a bucket that is already locked.")
RuntimeError: Attempted to lock a bucket that is already locked.

POST /channels/1120192393329770547/messages Has exceeded its ratelimit (5)! Reset in 5.986 seconds
POST /channels/1120192393329770547/messages Has exceeded its ratelimit (5)! Reset in 5.97 seconds
Ignoring exception in MessageCreate():
Traceback (most recent call last):
  File "/home/ubuntu/.local/lib/python3.10/site-packages/interactions/client/client.py", line 597, in _async_wrap
    await _coro(_event, *_args, **_kwargs)
  File "/home/ubuntu/.local/lib/python3.10/site-packages/interactions/models/internal/callback.py", line 31, in __call__
    return await self.callback(self._binding, *args, **kwargs)
  File "/home/ubuntu/FILO_LISTEN_BOT/App/apis/DiscordReply/BotEvent.py", line 147, in on_MessageCreate
    await message.reply(content = agency)
  File "/home/ubuntu/.local/lib/python3.10/site-packages/interactions/models/discord/message.py", line 701, in reply
    return await self.channel.send(content=content, reply_to=self, embeds=embeds or embed, **kwargs)
  File "/home/ubuntu/.local/lib/python3.10/site-packages/interactions/client/mixins/send.py", line 110, in send
    message_data = await self._send_http_request(message_payload, files=files or file)
  File "/home/ubuntu/.local/lib/python3.10/site-packages/interactions/models/discord/channel.py", line 247, in _send_http_request
    return await self._client.http.create_message(message_payload, self.id, files=files)
  File "/home/ubuntu/.local/lib/python3.10/site-packages/interactions/api/http/http_requests/messages.py", line 35, in create_message
    result = await self.request(
  File "/home/ubuntu/.local/lib/python3.10/site-packages/interactions/api/http/http_client.py", line 429, in request
    await lock.lock_for_duration(lock.delta, block=True)
  File "/home/ubuntu/.local/lib/python3.10/site-packages/interactions/api/http/http_client.py", line 179, in lock_for_duration
    raise RuntimeError("Attempted to lock a bucket that is already locked.")
RuntimeError: Attempted to lock a bucket that is already locked.

Ignoring exception in MessageCreate():
Traceback (most recent call last):
  File "/home/ubuntu/.local/lib/python3.10/site-packages/interactions/client/client.py", line 597, in _async_wrap
    await _coro(_event, *_args, **_kwargs)
  File "/home/ubuntu/.local/lib/python3.10/site-packages/interactions/models/internal/callback.py", line 31, in __call__
    return await self.callback(self._binding, *args, **kwargs)
  File "/home/ubuntu/FILO_LISTEN_BOT/App/apis/DiscordReply/BotEvent.py", line 147, in on_MessageCreate
    await message.reply(content = agency)
  File "/home/ubuntu/.local/lib/python3.10/site-packages/interactions/models/discord/message.py", line 701, in reply
    return await self.channel.send(content=content, reply_to=self, embeds=embeds or embed, **kwargs)
  File "/home/ubuntu/.local/lib/python3.10/site-packages/interactions/client/mixins/send.py", line 110, in send
    message_data = await self._send_http_request(message_payload, files=files or file)
  File "/home/ubuntu/.local/lib/python3.10/site-packages/interactions/models/discord/channel.py", line 247, in _send_http_request
    return await self._client.http.create_message(message_payload, self.id, files=files)
  File "/home/ubuntu/.local/lib/python3.10/site-packages/interactions/api/http/http_requests/messages.py", line 35, in create_message
    result = await self.request(
  File "/home/ubuntu/.local/lib/python3.10/site-packages/interactions/api/http/http_client.py", line 437, in request
    await lock.lock_for_duration(
  File "/home/ubuntu/.local/lib/python3.10/site-packages/interactions/api/http/http_client.py", line 179, in lock_for_duration
    raise RuntimeError("Attempted to lock a bucket that is already locked.")
RuntimeError: Attempted to lock a bucket that is already locked.

POST /channels/1120192393329770547/messages Has exceeded its ratelimit (5)! Reset in 5.966 seconds
Ignoring exception in MessageCreate():
Traceback (most recent call last):
  File "/home/ubuntu/.local/lib/python3.10/site-packages/interactions/client/client.py", line 597, in _async_wrap
    await _coro(_event, *_args, **_kwargs)
  File "/home/ubuntu/.local/lib/python3.10/site-packages/interactions/models/internal/callback.py", line 31, in __call__
    return await self.callback(self._binding, *args, **kwargs)
  File "/home/ubuntu/FILO_LISTEN_BOT/App/apis/DiscordReply/BotEvent.py", line 147, in on_MessageCreate
    await message.reply(content = agency)
  File "/home/ubuntu/.local/lib/python3.10/site-packages/interactions/models/discord/message.py", line 701, in reply
    return await self.channel.send(content=content, reply_to=self, embeds=embeds or embed, **kwargs)
  File "/home/ubuntu/.local/lib/python3.10/site-packages/interactions/client/mixins/send.py", line 110, in send
    message_data = await self._send_http_request(message_payload, files=files or file)
  File "/home/ubuntu/.local/lib/python3.10/site-packages/interactions/models/discord/channel.py", line 247, in _send_http_request
    return await self._client.http.create_message(message_payload, self.id, files=files)
  File "/home/ubuntu/.local/lib/python3.10/site-packages/interactions/api/http/http_requests/messages.py", line 35, in create_message
    result = await self.request(
  File "/home/ubuntu/.local/lib/python3.10/site-packages/interactions/api/http/http_client.py", line 437, in request
    await lock.lock_for_duration(
  File "/home/ubuntu/.local/lib/python3.10/site-packages/interactions/api/http/http_client.py", line 179, in lock_for_duration
    raise RuntimeError("Attempted to lock a bucket that is already locked.")
RuntimeError: Attempted to lock a bucket that is already locked.

Gateway has invalidated session! Reconnecting...
